<?xml version="1.0"?>
<robot xmlns:xacro="http://www.ros.org/wiki/xacro">
   <xacro:include filename="inertial_macros.xacro"/>
   
    <material name="white">
        <color rgba="1 1 1 1"/>
    </material>

    <material name="orange">
        <color rgba="1 0.3 0.1 1"/>
    </material>

    <material name="blue">
        <color rgba="0.2 0.2 1 1"/>
    </material>

    <material name="black">
        <color rgba="0 0 0 0.7"/>
    </material>


    <!-- BASE LINK -->

    <link name="base_link">

    </link>

    <!-- CHASSIS LINK -->
    
    <joint name="chassis_joint" type="fixed">
        <parent link="base_link"/>
        <child link="chassis"/>
        <origin xyz="-0.19 0 0"/>
    </joint>

    <link name="chassis">
        <visual>
            <origin xyz="0.19 0 0"/>
            <geometry>
                <box size="0.38 0.02 0.02"/>
            </geometry>
            <material name="black"/>
        </visual>
        <collision>
            <origin xyz="0.19 0 0"/>
            <geometry>
                <box size="0.38 0.02 0.02"/>
            </geometry>
        </collision>
        <xacro:inertial_box mass="0.5" x="0.5" y="0.5" z="0.02">
            <origin xyz="0.19 0 0.01" rpy="0 0 0"/>
        </xacro:inertial_box>
    </link>
    <gazebo reference="chassis">
       <material>Gazebo/Black</material>
    </gazebo>
    



  <!-- FRONT CHASSIS LINK -->
    
    <joint name="front_chassis_joint" type="fixed">
        <parent link="base_link"/>
        <child link="front_chassis"/>
        <origin xyz="0.2 0 0"/>
    </joint>

    <link name="front_chassis">
        <visual>
            <origin xyz="0 0 0"/>
            <geometry>
                <box size="0.02 0.4 0.02"/>
            </geometry>
            <material name="black"/>
        </visual>
        <collision>
            <origin xyz="0 0 0"/>
            <geometry>
                <box size="0.02 0.4 0.02"/>
            </geometry>
        </collision>
        <xacro:inertial_box mass="0.5" x="0.5" y="0.5" z="0.02">
            <origin xyz="0 0 0.01" rpy="0 0 0"/>
        </xacro:inertial_box>
    </link>
    <gazebo reference="front_chassis">
       <material>Gazebo/Black</material>
    </gazebo>




     <!--BACK CHASSIS LINK -->
    
    <joint name="back_chassis_joint" type="fixed">
        <parent link="base_link"/>
        <child link="back_chassis"/>
        <origin xyz="-0.2 0 0"/>
    </joint>

    <link name="back_chassis">
        <visual>
            <origin xyz="0 0 0"/>
            <geometry>
                <box size="0.02 0.4 0.02"/>
            </geometry>
            <material name="black"/>
        </visual>
        <collision>
            <origin xyz="0 0 0"/>
            <geometry>
                <box size="0.02 0.4 0.02"/>
            </geometry>
        </collision>
        <xacro:inertial_box mass="0.5" x="0.5" y="0.5" z="0.02">
            <origin xyz="0 0 0.01" rpy="0 0 0"/>
        </xacro:inertial_box>
    </link>
    <gazebo reference="back_chassis">
       <material>Gazebo/Black</material>
    </gazebo>



     <!-- ROBOT BASE LINK -->
    
    <joint name="base_joint" type="fixed">
        <parent link="base_link"/>
        <child link="base"/>
        <origin xyz="0 0 0.2"/>
    </joint>

    <link name="base">
        <visual>
            <origin xyz="0 0 -0.1"/>
            <geometry>
                <box size="0.02 0.02 0.2"/>
            </geometry>
            <material name="white"/>
        </visual>
        <collision>
            <origin xyz="0 0 -0.1"/>
            <geometry>
                <box size="0.02 0.02 0.2"/>
            </geometry>
        </collision>
        <xacro:inertial_box mass="0.1" x="0.02" y="0.02" z="0.2">
            <origin xyz="0 0 0.1" rpy="0 0 0"/>
        </xacro:inertial_box>
    </link>
    <gazebo reference="base">
       <material>Gazebo/White</material>
    </gazebo>
    
    

 
 
    
    <!-- ROBOT ROLL LINK -->
    
    <joint name="roll_joint" type="revolute">
        <parent link="base"/>
        <child link="roll"/>
        <origin xyz="0 0 0"/>
        <limit lower="-1" upper="1" effort="10" velocity="3"/>
        <axis xyz="1 0 0"/>
    </joint>

    <link name="roll">
        <visual>
            <origin xyz="0 0 0"/>
            <geometry>
                <box size="0 0 0"/>
            </geometry>
            <material name="white"/>
        </visual>
        <collision>
            <origin xyz="0 0 0"/>
            <geometry>
                <box size="0 0 0"/>
            </geometry>
        </collision>
        <xacro:inertial_box mass="0.09" x="0.05" y="0.02" z="0.02">
            <origin xyz="0.05 0 0" rpy="0 0 0"/>
        </xacro:inertial_box>
    </link>
    <gazebo reference="roll">
       <material>Gazebo/White</material>
    </gazebo>
    
    
    <!-- ROBOT PITCH LINK -->
    
    <joint name="pitch_joint" type="revolute">
        <parent link="roll"/>
        <child link="pitch"/>
        <origin xyz="0 0 0"/>
        <limit lower="-1" upper="1" effort="10" velocity="3"/>
        <axis xyz="0 1 0"/>
    </joint>

    <link name="pitch">
        <visual>
            <origin xyz="0 0 0"/>
            <geometry>
                <box size="0 0 0"/>
            </geometry>
            <material name="white"/>
        </visual>
        <collision>
            <origin xyz="0 0 0"/>
            <geometry>
                <box size="0 0 0"/>
            </geometry>
        </collision>
        <xacro:inertial_box mass="0.09" x="0.02" y="0.05" z="0.02">
            <origin xyz="0 0.05 0" rpy="0 0 0"/>
        </xacro:inertial_box>
    </link>
    <gazebo reference="pitch">
       <material>Gazebo/White</material>
    </gazebo>
    
    
    
        <!-- ROBOT Yaw LINK -->
    
    <joint name="yaw_joint" type="continuous">
        <parent link="pitch"/>
        <child link="yaw"/>
        <origin xyz="0 0 0.04"/>
        <axis xyz="0 0 1"/>
    </joint>

    <link name="yaw">
        <visual>
            <origin xyz="0 0 -0.02"/>
            <geometry>
                <cylinder radius="0.01" length="0.04"/>
            </geometry>
            <material name="orange"/>
        </visual>
        <collision>
            <origin xyz="0 0 -0.02"/>
            <geometry>
                <cylinder radius="0.01" length="0.04"/>
            </geometry>
        </collision>
        <xacro:inertial_cylinder mass="0.01" length="0.04" radius="0.01">
            <origin xyz="0 0 0" rpy="0 0 0"/>
        </xacro:inertial_cylinder>
    </link>
    <gazebo reference="yaw">
       <material>Gazebo/Orange</material>
    </gazebo>
    
    
    
         <!-- ROBOT PLATE LINK -->
    
    <joint name="plate_joint" type="fixed">
        <parent link="yaw"/>
        <child link="plate"/>
        <origin xyz="0 0 0"/>
    </joint>

    <link name="plate">
        <visual>
            <origin xyz="0 0 0"/>
            <geometry>
                <box size="0.1 0.1 0.001"/>
            </geometry>
            <material name="white"/>
        </visual>
        <collision>
            <origin xyz="0 0 0"/>
            <geometry>
                <box size="0.1 0.1 0.001"/>
            </geometry>
        </collision>
        <xacro:inertial_box mass="0.09" x="0.02" y="0.05" z="0.02">
            <origin xyz="0 0.05 0" rpy="0 0 0"/>
        </xacro:inertial_box>
    </link>
    <gazebo reference="plate">
       <material>Gazebo/White</material>
    </gazebo>
    
       
    <!-- CAMERA BASE LINK -->
    
    <joint name="camera_base_joint" type="fixed">
        <parent link="base_link"/>
        <child link="camera_base"/>
        <origin xyz="0.15 0 0.1"/>
    </joint>

    <link name="camera_base">
        <visual>
            <origin xyz="0 0 -0.05"/>
            <geometry>
                <box size="0.01 0.01 0.1"/>
            </geometry>
            <material name="orange"/>
        </visual>
        <collision>
            <origin xyz="0 0 -0.05"/>
            <geometry>
                <box size="0.01 0.01 0.1"/>
            </geometry>
        </collision>
        <xacro:inertial_box mass="0.05" x="0.02" y="0.02" z="0.1">
            <origin xyz="0 0 0.05" rpy="0 0 0"/>
        </xacro:inertial_box>
    </link> 
    <gazebo reference="camera_base">
       <material>Gazebo/Orange</material>
    </gazebo>
    
    
    
     <!-- LEFT WHEEL LINK -->

    <joint name="left_wheel_joint" type="continuous">
        <parent link="chassis"/>
        <child link="left_wheel"/>
        <origin xyz="0 0.19 -0.04" rpy="-${pi/2} 0 0"/>
        <axis xyz="0 0 1"/>
    </joint>

    <link name="left_wheel">
        <visual>
            <geometry>
                <cylinder radius="0.02" length="0.02"/>
            </geometry>
            <material name="blue"/>
        </visual>
        <collision>
            <geometry>
                <cylinder radius="0.02" length="0.02"/>
            </geometry>
        </collision>
        <xacro:inertial_cylinder mass="0.1" length="0.02" radius="0.02">
            <origin xyz="0 0 0" rpy="0 0 0"/>
        </xacro:inertial_cylinder>
        
    </link>
    <gazebo reference="left_wheel">
       <material>Gazebo/Blue</material>
    </gazebo>

    <!-- RIGHT WHEEL LINK -->

    <joint name="right_wheel_joint" type="continuous">
        <parent link="chassis"/>
        <child link="right_wheel"/>
        <origin xyz="0 -0.19 -0.04" rpy="${pi/2} 0 0" />
        <axis xyz="0 0 -1"/>
    </joint>

    <link name="right_wheel">
        <visual>
            <geometry>
                <cylinder radius="0.02" length="0.02"/>
            </geometry>
            <material name="blue"/>
        </visual>
        <collision>
            <geometry>
                <cylinder radius="0.02" length="0.02"/>
            </geometry>
        </collision>
        <xacro:inertial_cylinder mass="0.1" length="0.02" radius="0.02">
            <origin xyz="0 0 0" rpy="0 0 0"/>
        </xacro:inertial_cylinder>
        
    </link>
    <gazebo reference="right_wheel">
       <material>Gazebo/Blue</material>
    </gazebo>

    <!-- FIRST CASTER WHEEL LINK -->

    <joint name="caster_wheel1_joint" type="fixed">
        <parent link="base_link"/>
        <child link="caster_wheel1"/>
        <origin xyz="0.20 -0.2 -0.04"/>
    </joint>


    <link name="caster_wheel1">
        <visual>
            <geometry>
                <sphere radius="0.02"/>
            </geometry>
            <material name="blue"/>
        </visual>
        <collision>
            <geometry>
                <sphere radius="0.02"/>
            </geometry>
        </collision>
        <xacro:inertial_sphere mass="0.1" radius="0.02">
            <origin xyz="0 0 0" rpy="0 0 0"/>
        </xacro:inertial_sphere>
        
    </link>
    <gazebo reference="caster_wheel1">
       <material>Gazebo/Blue</material>
       <mu1 value="0.001"/>
       <mu2 value="0.001"/>
    </gazebo>
    
    <!-- SECOND CASTER WHEEL LINK -->

    <joint name="caster_wheel2_joint" type="fixed">
        <parent link="base_link"/>
        <child link="caster_wheel2"/>
        <origin xyz="0.2 0.2 -0.04"/>
    </joint>


    <link name="caster_wheel2">
        <visual>
            <geometry>
                <sphere radius="0.02"/>
            </geometry>
            <material name="blue"/>
        </visual>
        <collision>
            <geometry>
                <sphere radius="0.02"/>
            </geometry>
        </collision>
        <xacro:inertial_sphere mass="0.1" radius="0.02">
            <origin xyz="0 0 0" rpy="0 0 0"/>
        </xacro:inertial_sphere>
        
    </link>
    <gazebo reference="caster_wheel2">
       <material>Gazebo/Blue</material>
       <mu1 value="0.001"/>
       <mu2 value="0.001"/>
    </gazebo>
    

</robot>
